Workbook

Sheet Planung
A1: week | B1: date | C1: day | D1: coating 1 | E1: production 1 (h) | F1: coating 2 | G1: production 2 (h) | H1: output target 1 (M²) | I1: output target 2 (M²) | J1: yield target (M²) | K1: Available for Sales | L1: Comment | M1: Umstellung
A2: =_xlfn.ISOWEEKNUM(B2) -> 53 | B2: 44193 | C2: Montag | E2: =IF(VLOOKUP(D2,Budget!A:B,2,FALSE)<>0,IF(G2=0,24,24-G2),0) -> #N/A | H2: =IF(E2=0,0,IF(M2="ja",(VLOOKUP(D2,Budget!A:F,6,FALSE)*(E2-(VLOOKUP(D2,Budget!A:F,3,FALSE)))),VLOOKUP($D2,Budget!$A$1:$F$19,6,FALSE)*E2)) -> #N/A | I2: =IF(F2=0,0,IF(M2="ja",((VLOOKUP(F2,Budget!A:F,6,FALSE)*(E2-(VLOOKUP(F2,Budget!A:F,3,FALSE))))),VLOOKUP($D2,Budget!A:F,5,FALSE)*E2)) -> 0 | J2: =H2+I2 -> #N/A | M2: nein | N2: =YEAR(B2) -> 2020
A3: =_xlfn.ISOWEEKNUM(B3) -> 53 | B3: 44194 | C3: Dienstag | E3: =IF(VLOOKUP(D3,Budget!A:B,2,FALSE)<>0,IF(G3=0,24,24-G3),0) -> #N/A | H3: =IF(E3=0,0,IF(M3="ja",(VLOOKUP(D3,Budget!A:F,6,FALSE)*(E3-(VLOOKUP(D3,Budget!A:F,3,FALSE)))),VLOOKUP($D3,Budget!$A$1:$F$19,6,FALSE)*E3)) -> #N/A | I3: =IF(F3=0,0,IF(M3="ja",((VLOOKUP(F3,Budget!A:F,6,FALSE)*(E3-(VLOOKUP(F3,Budget!A:F,3,FALSE))))),VLOOKUP($D3,Budget!A:F,5,FALSE)*E3)) -> 0 | J3: =H3+I3 -> #N/A | L3: Abbruch wegen WAMA-Spuren | M3: =IF(E3=0,"nein",IF(OR(E3<>24,F2<>0,D3<>D2),"ja","nein")) -> #N/A | N3: =YEAR(B3) -> 2020
A4: =_xlfn.ISOWEEKNUM(B4) -> 53 | B4: 44195 | C4: Mittwoch | E4: =IF(VLOOKUP(D4,Budget!A:B,2,FALSE)<>0,IF(G4=0,24,24-G4),0) -> #N/A | H4: =IF(E4=0,0,IF(M4="ja",(VLOOKUP(D4,Budget!A:F,6,FALSE)*(E4-(VLOOKUP(D4,Budget!A:F,3,FALSE)))),VLOOKUP($D4,Budget!$A$1:$F$19,6,FALSE)*E4)) -> #N/A | I4: =IF(F4=0,0,IF(M4="ja",((VLOOKUP(F4,Budget!A:F,6,FALSE)*(E4-(VLOOKUP(F4,Budget!A:F,3,FALSE))))),VLOOKUP($D4,Budget!A:F,5,FALSE)*E4)) -> 0 | J4: =H4+I4 -> #N/A | M4: =IF(E4=0,"nein",IF(OR(E4<>24,F3<>0,D4<>D3),"ja","nein")) -> #N/A | N4: =YEAR(B4) -> 2020
A5: =_xlfn.ISOWEEKNUM(B5) -> 53 | B5: 44196 | C5: Donnerstag | E5: =IF(VLOOKUP(D5,Budget!A:B,2,FALSE)<>0,IF(G5=0,24,24-G5),0) -> #N/A | H5: =IF(E5=0,0,IF(M5="ja",(VLOOKUP(D5,Budget!A:F,6,FALSE)*(E5-(VLOOKUP(D5,Budget!A:F,3,FALSE)))),VLOOKUP($D5,Budget!$A$1:$F$19,6,FALSE)*E5)) -> #N/A | I5: =IF(F5=0,0,IF(M5="ja",((VLOOKUP(F5,Budget!A:F,6,FALSE)*(E5-(VLOOKUP(F5,Budget!A:F,3,FALSE))))),VLOOKUP($D5,Budget!A:F,5,FALSE)*E5)) -> 0 | J5: =H5+I5 -> #N/A | M5: =IF(E5=0,"nein",IF(OR(E5<>24,F4<>0,D5<>D4),"ja","nein")) -> #N/A | N5: =YEAR(B5) -> 2020
A6: =_xlfn.ISOWEEKNUM(B6) -> 53 | B6: 44197 | C6: Freitag | E6: =IF(VLOOKUP(D6,Budget!A:B,2,FALSE)<>0,IF(G6=0,24,24-G6),0) -> #N/A | H6: =IF(E6=0,0,IF(M6="ja",(VLOOKUP(D6,Budget!A:F,6,FALSE)*(E6-(VLOOKUP(D6,Budget!A:F,3,FALSE)))),VLOOKUP($D6,Budget!$A$1:$F$19,6,FALSE)*E6)) -> #N/A | I6: =IF(F6=0,0,IF(M6="ja",((VLOOKUP(F6,Budget!A:F,6,FALSE)*(E6-(VLOOKUP(F6,Budget!A:F,3,FALSE))))),VLOOKUP($D6,Budget!A:F,5,FALSE)*E6)) -> 0 | J6: =H6+I6 -> #N/A | L6: Abbruch wegen Kratzern | M6: =IF(E6=0,"nein",IF(OR(E6<>24,F5<>0,D6<>D5),"ja","nein")) -> #N/A | N6: =YEAR(B6) -> 2021
A7: =_xlfn.ISOWEEKNUM(B7) -> 53 | B7: 44198 | C7: Samstag | D7: W | E7: =IF(VLOOKUP(D7,Budget!A:B,2,FALSE)<>0,IF(G7=0,24,24-G7),0) -> 0 | H7: =IF(E7=0,0,IF(M7="ja",(VLOOKUP(D7,Budget!A:F,6,FALSE)*(E7-(VLOOKUP(D7,Budget!A:F,3,FALSE)))),VLOOKUP($D7,Budget!$A$1:$F$19,6,FALSE)*E7)) -> 0 | I7: =IF(F7=0,0,IF(M7="ja",((VLOOKUP(F7,Budget!A:F,6,FALSE)*(E7-(VLOOKUP(F7,Budget!A:F,3,FALSE))))),VLOOKUP($D7,Budget!A:F,5,FALSE)*E7)) -> 0 | J7: =H7+I7 -> 0 | L7: Fluten & PLT XN | M7: =IF(E7=0,"nein",IF(OR(E7<>24,F6<>0,D7<>D6),"ja","nein")) -> nein | N7: =YEAR(B7) -> 2021
A8: =_xlfn.ISOWEEKNUM(B8) -> 53 | B8: 44199 | C8: Sonntag | D8: PLT XN | E8: =IF(VLOOKUP(D8,Budget!A:B,2,FALSE)<>0,IF(G8=0,24,24-G8),0) -> 24 | H8: =IF(E8=0,0,IF(M8="ja",(VLOOKUP(D8,Budget!A:F,6,FALSE)*(E8-(VLOOKUP(D8,Budget!A:F,3,FALSE)))),VLOOKUP($D8,Budget!$A$1:$F$19,6,FALSE)*E8)) -> 38269.757 | I8: =IF(F8=0,0,IF(M8="ja",((VLOOKUP(F8,Budget!A:F,6,FALSE)*(E8-(VLOOKUP(F8,Budget!A:F,3,FALSE))))),VLOOKUP($D8,Budget!A:F,5,FALSE)*E8)) -> 0 | J8: =H8+I8 -> 38269.757 | M8: =IF(E8=0,"nein",IF(OR(E8<>24,F7<>0,D8<>D7),"ja","nein")) -> ja | N8: =YEAR(B8) -> 2021
A9: =_xlfn.ISOWEEKNUM(B9) -> 1 | B9: 44200 | C9: Montag | D9: PLT XN | E9: =IF(VLOOKUP(D9,Budget!A:B,2,FALSE)<>0,IF(G9=0,24,24-G9),0) -> 24 | H9: =IF(E9=0,0,IF(M9="ja",(VLOOKUP(D9,Budget!A:F,6,FALSE)*(E9-(VLOOKUP(D9,Budget!A:F,3,FALSE)))),VLOOKUP($D9,Budget!$A$1:$F$19,6,FALSE)*E9)) -> 42919.354 | I9: =IF(F9=0,0,IF(M9="ja",((VLOOKUP(F9,Budget!A:F,6,FALSE)*(E9-(VLOOKUP(F9,Budget!A:F,3,FALSE))))),VLOOKUP($D9,Budget!A:F,5,FALSE)*E9)) -> 0 | J9: =H9+I9 -> 42919.354 | M9: nein | N9: =YEAR(B9) -> 2021
A10: =_xlfn.ISOWEEKNUM(B10) -> 1 | B10: 44201 | C10: Dienstag | D10: PLT XNII | E10: =IF(VLOOKUP(D10,Budget!A:B,2,FALSE)<>0,IF(G10=0,24,24-G10),0) -> 24 | H10: =IF(E10=0,0,IF(M10="ja",(VLOOKUP(D10,Budget!A:F,6,FALSE)*(E10-(VLOOKUP(D10,Budget!A:F,3,FALSE)))),VLOOKUP($D10,Budget!$A$1:$F$19,6,FALSE)*E10)) -> 22220.984 | I10: =IF(F10=0,0,IF(M10="ja",((VLOOKUP(F10,Budget!A:F,6,FALSE)*(E10-(VLOOKUP(F10,Budget!A:F,3,FALSE))))),VLOOKUP($D10,Budget!A:F,5,FALSE)*E10)) -> 0 | J10: =H10+I10 -> 22220.984 | M10: =IF(E10=0,"nein",IF(OR(E10<>24,F9<>0,D10<>D9),"ja","nein")) -> ja | N10: =YEAR(B10) -> 2021
A11: =_xlfn.ISOWEEKNUM(B11) -> 1 | B11: 44202 | C11: Mittwoch | D11: PLT XNII | E11: =IF(VLOOKUP(D11,Budget!A:B,2,FALSE)<>0,IF(G11=0,24,24-G11),0) -> 24 | H11: =IF(E11=0,0,IF(M11="ja",(VLOOKUP(D11,Budget!A:F,6,FALSE)*(E11-(VLOOKUP(D11,Budget!A:F,3,FALSE)))),VLOOKUP($D11,Budget!$A$1:$F$19,6,FALSE)*E11)) -> 35553.574 | I11: =IF(F11=0,0,IF(M11="ja",((VLOOKUP(F11,Budget!A:F,6,FALSE)*(E11-(VLOOKUP(F11,Budget!A:F,3,FALSE))))),VLOOKUP($D11,Budget!A:F,5,FALSE)*E11)) -> 0 | J11: =H11+I11 -> 35553.574 | M11: =IF(E11=0,"nein",IF(OR(E11<>24,F10<>0,D11<>D10),"ja","nein")) -> nein | N11: =YEAR(B11) -> 2021
A12: =_xlfn.ISOWEEKNUM(B12) -> 1 | B12: 44203 | C12: Donnerstag | D12: ECLAZ | E12: =IF(VLOOKUP(D12,Budget!A:B,2,FALSE)<>0,IF(G12=0,24,24-G12),0) -> 24 | H12: =IF(E12=0,0,IF(M12="ja",(VLOOKUP(D12,Budget!A:F,6,FALSE)*(E12-(VLOOKUP(D12,Budget!A:F,3,FALSE)))),VLOOKUP($D12,Budget!$A$1:$F$19,6,FALSE)*E12)) -> 30030 | I12: =IF(F12=0,0,IF(M12="ja",((VLOOKUP(F12,Budget!A:F,6,FALSE)*(E12-(VLOOKUP(F12,Budget!A:F,3,FALSE))))),VLOOKUP($D12,Budget!A:F,5,FALSE)*E12)) -> 0 | J12: =H12+I12 -> 30030 | M12: =IF(E12=0,"nein",IF(OR(E12<>24,F11<>0,D12<>D11),"ja","nein")) -> ja | N12: =YEAR(B12) -> 2021
A13: =_xlfn.ISOWEEKNUM(B13) -> 1 | B13: 44204 | C13: Freitag | D13: ECLAZ | E13: =IF(VLOOKUP(D13,Budget!A:B,2,FALSE)<>0,IF(G13=0,24,24-G13),0) -> 24 | H13: =IF(E13=0,0,IF(M13="ja",(VLOOKUP(D13,Budget!A:F,6,FALSE)*(E13-(VLOOKUP(D13,Budget!A:F,3,FALSE)))),VLOOKUP($D13,Budget!$A$1:$F$19,6,FALSE)*E13)) -> 36960 | I13: =IF(F13=0,0,IF(M13="ja",((VLOOKUP(F13,Budget!A:F,6,FALSE)*(E13-(VLOOKUP(F13,Budget!A:F,3,FALSE))))),VLOOKUP($D13,Budget!A:F,5,FALSE)*E13)) -> 0 | J13: =H13+I13 -> 36960 | M13: =IF(E13=0,"nein",IF(OR(E13<>24,F12<>0,D13<>D12),"ja","nein")) -> nein | N13: =YEAR(B13) -> 2021
A14: =_xlfn.ISOWEEKNUM(B14) -> 1 | B14: 44205 | C14: Samstag | D14: ECLAZ | E14: =IF(VLOOKUP(D14,Budget!A:B,2,FALSE)<>0,IF(G14=0,24,24-G14),0) -> 24 | H14: =IF(E14=0,0,IF(M14="ja",(VLOOKUP(D14,Budget!A:F,6,FALSE)*(E14-(VLOOKUP(D14,Budget!A:F,3,FALSE)))),VLOOKUP($D14,Budget!$A$1:$F$19,6,FALSE)*E14)) -> 36960 | I14: =IF(F14=0,0,IF(M14="ja",((VLOOKUP(F14,Budget!A:F,6,FALSE)*(E14-(VLOOKUP(F14,Budget!A:F,3,FALSE))))),VLOOKUP($D14,Budget!A:F,5,FALSE)*E14)) -> 0 | J14: =H14+I14 -> 36960 | M14: =IF(E14=0,"nein",IF(OR(E14<>24,F13<>0,D14<>D13),"ja","nein")) -> nein | N14: =YEAR(B14) -> 2021
A15: =_xlfn.ISOWEEKNUM(B15) -> 1 | B15: 44206 | C15: Sonntag | D15: ECLAZ | E15: =IF(VLOOKUP(D15,Budget!A:B,2,FALSE)<>0,IF(G15=0,24,24-G15),0) -> 24 | H15: =IF(E15=0,0,IF(M15="ja",(VLOOKUP(D15,Budget!A:F,6,FALSE)*(E15-(VLOOKUP(D15,Budget!A:F,3,FALSE)))),VLOOKUP($D15,Budget!$A$1:$F$19,6,FALSE)*E15)) -> 36960 | I15: =IF(F15=0,0,IF(M15="ja",((VLOOKUP(F15,Budget!A:F,6,FALSE)*(E15-(VLOOKUP(F15,Budget!A:F,3,FALSE))))),VLOOKUP($D15,Budget!A:F,5,FALSE)*E15)) -> 0 | J15: =H15+I15 -> 36960 | M15: =IF(E15=0,"nein",IF(OR(E15<>24,F14<>0,D15<>D14),"ja","nein")) -> nein | N15: =YEAR(B15) -> 2021
A16: =_xlfn.ISOWEEKNUM(B16) -> 2 | B16: 44207 | C16: Montag | D16: ECLAZ | E16: =IF(VLOOKUP(D16,Budget!A:B,2,FALSE)<>0,IF(G16=0,24,24-G16),0) -> 24 | H16: =IF(E16=0,0,IF(M16="ja",(VLOOKUP(D16,Budget!A:F,6,FALSE)*(E16-(VLOOKUP(D16,Budget!A:F,3,FALSE)))),VLOOKUP($D16,Budget!$A$1:$F$19,6,FALSE)*E16)) -> 36960 | I16: =IF(F16=0,0,IF(M16="ja",((VLOOKUP(F16,Budget!A:F,6,FALSE)*(E16-(VLOOKUP(F16,Budget!A:F,3,FALSE))))),VLOOKUP($D16,Budget!A:F,5,FALSE)*E16)) -> 0 | J16: =H16+I16 -> 36960 | M16: =IF(E16=0,"nein",IF(OR(E16<>24,F15<>0,D16<>D15),"ja","nein")) -> nein | N16: =YEAR(B16) -> 2021
A17: =_xlfn.ISOWEEKNUM(B17) -> 2 | B17: 44208 | C17: Dienstag | D17: ECLAZ | E17: =IF(VLOOKUP(D17,Budget!A:B,2,FALSE)<>0,IF(G17=0,24,24-G17),0) -> 24 | H17: =IF(E17=0,0,IF(M17="ja",(VLOOKUP(D17,Budget!A:F,6,FALSE)*(E17-(VLOOKUP(D17,Budget!A:F,3,FALSE)))),VLOOKUP($D17,Budget!$A$1:$F$19,6,FALSE)*E17)) -> 36960 | I17: =IF(F17=0,0,IF(M17="ja",((VLOOKUP(F17,Budget!A:F,6,FALSE)*(E17-(VLOOKUP(F17,Budget!A:F,3,FALSE))))),VLOOKUP($D17,Budget!A:F,5,FALSE)*E17)) -> 0 | J17: =H17+I17 -> 36960 | M17: =IF(E17=0,"nein",IF(OR(E17<>24,F16<>0,D17<>D16),"ja","nein")) -> nein | N17: =YEAR(B17) -> 2021
A18: =_xlfn.ISOWEEKNUM(B18) -> 2 | B18: 44209 | C18: Mittwoch | D18: PLT XN | E18: =IF(VLOOKUP(D18,Budget!A:B,2,FALSE)<>0,IF(G18=0,24,24-G18),0) -> 24 | H18: =IF(E18=0,0,IF(M18="ja",(VLOOKUP(D18,Budget!A:F,6,FALSE)*(E18-(VLOOKUP(D18,Budget!A:F,3,FALSE)))),VLOOKUP($D18,Budget!$A$1:$F$19,6,FALSE)*E18)) -> 38269.757 | I18: =IF(F18=0,0,IF(M18="ja",((VLOOKUP(F18,Budget!A:F,6,FALSE)*(E18-(VLOOKUP(F18,Budget!A:F,3,FALSE))))),VLOOKUP($D18,Budget!A:F,5,FALSE)*E18)) -> 0 | J18: =H18+I18 -> 38269.757 | M18: =IF(E18=0,"nein",IF(OR(E18<>24,F17<>0,D18<>D17),"ja","nein")) -> ja | N18: =YEAR(B18) -> 2021
A19: =_xlfn.ISOWEEKNUM(B19) -> 2 | B19: 44210 | C19: Donnerstag | D19: PLT XN | E19: =IF(VLOOKUP(D19,Budget!A:B,2,FALSE)<>0,IF(G19=0,24,24-G19),0) -> 24 | H19: =IF(E19=0,0,IF(M19="ja",(VLOOKUP(D19,Budget!A:F,6,FALSE)*(E19-(VLOOKUP(D19,Budget!A:F,3,FALSE)))),VLOOKUP($D19,Budget!$A$1:$F$19,6,FALSE)*E19)) -> 42919.354 | I19: =IF(F19=0,0,IF(M19="ja",((VLOOKUP(F19,Budget!A:F,6,FALSE)*(E19-(VLOOKUP(F19,Budget!A:F,3,FALSE))))),VLOOKUP($D19,Budget!A:F,5,FALSE)*E19)) -> 0 | J19: =H19+I19 -> 42919.354 | M19: =IF(E19=0,"nein",IF(OR(E19<>24,F18<>0,D19<>D18),"ja","nein")) -> nein | N19: =YEAR(B19) -> 2021
A20: =_xlfn.ISOWEEKNUM(B20) -> 2 | B20: 44211 | C20: Freitag | D20: SIGMA | E20: =IF(VLOOKUP(D20,Budget!A:B,2,FALSE)<>0,IF(G20=0,24,24-G20),0) -> 0 | G20: W | H20: =IF(E20=0,0,IF(M20="ja",(VLOOKUP(D20,Budget!A:F,6,FALSE)*(E20-(VLOOKUP(D20,Budget!A:F,3,FALSE)))),VLOOKUP($D20,Budget!$A$1:$F$19,6,FALSE)*E20)) -> 0 | I20: =IF(F20=0,0,IF(M20="ja",((VLOOKUP(F20,Budget!A:F,6,FALSE)*(E20-(VLOOKUP(F20,Budget!A:F,3,FALSE))))),VLOOKUP($D20,Budget!A:F,5,FALSE)*E20)) -> 0 | J20: =H20+I20 -> 0 | L20: BIO-Versuch 18 - 20h | M20: =IF(E20=0,"nein",IF(OR(E20<>24,F19<>0,D20<>D19),"ja","nein")) -> nein | N20: =YEAR(B20) -> 2021
A21: =_xlfn.ISOWEEKNUM(B21) -> 2 | B21: 44212 | C21: Samstag | D21: W | E21: =IF(VLOOKUP(D21,Budget!A:B,2,FALSE)<>0,IF(G21=0,24,24-G21),0) -> 0 | H21: =IF(E21=0,0,IF(M21="ja",(VLOOKUP(D21,Budget!A:F,6,FALSE)*(E21-(VLOOKUP(D21,Budget!A:F,3,FALSE)))),VLOOKUP($D21,Budget!$A$1:$F$19,6,FALSE)*E21)) -> 0 | I21: =IF(F21=0,0,IF(M21="ja",((VLOOKUP(F21,Budget!A:F,6,FALSE)*(E21-(VLOOKUP(F21,Budget!A:F,3,FALSE))))),VLOOKUP($D21,Budget!A:F,5,FALSE)*E21)) -> 0 | J21: =H21+I21 -> 0 | M21: =IF(E21=0,"nein",IF(OR(E21<>24,F20<>0,D21<>D20),"ja","nein")) -> nein | N21: =YEAR(B21) -> 2021
A22: =_xlfn.ISOWEEKNUM(B22) -> 2 | B22: 44213 | C22: Sonntag | D22: W | E22: =IF(VLOOKUP(D22,Budget!A:B,2,FALSE)<>0,IF(G22=0,24,24-G22),0) -> 0 | H22: =IF(E22=0,0,IF(M22="ja",(VLOOKUP(D22,Budget!A:F,6,FALSE)*(E22-(VLOOKUP(D22,Budget!A:F,3,FALSE)))),VLOOKUP($D22,Budget!$A$1:$F$19,6,FALSE)*E22)) -> 0 | I22: =IF(F22=0,0,IF(M22="ja",((VLOOKUP(F22,Budget!A:F,6,FALSE)*(E22-(VLOOKUP(F22,Budget!A:F,3,FALSE))))),VLOOKUP($D22,Budget!A:F,5,FALSE)*E22)) -> 0 | J22: =H22+I22 -> 0 | M22: =IF(E22=0,"nein",IF(OR(E22<>24,F21<>0,D22<>D21),"ja","nein")) -> nein | N22: =YEAR(B22) -> 2021
A23: =_xlfn.ISOWEEKNUM(B23) -> 3 | B23: 44214 | C23: Montag | D23: W | E23: =IF(VLOOKUP(D23,Budget!A:B,2,FALSE)<>0,IF(G23=0,24,24-G23),0) -> 0 | H23: =IF(E23=0,0,IF(M23="ja",(VLOOKUP(D23,Budget!A:F,6,FALSE)*(E23-(VLOOKUP(D23,Budget!A:F,3,FALSE)))),VLOOKUP($D23,Budget!$A$1:$F$19,6,FALSE)*E23)) -> 0 | I23: =IF(F23=0,0,IF(M23="ja",((VLOOKUP(F23,Budget!A:F,6,FALSE)*(E23-(VLOOKUP(F23,Budget!A:F,3,FALSE))))),VLOOKUP($D23,Budget!A:F,5,FALSE)*E23)) -> 0 | J23: =H23+I23 -> 0 | M23: =IF(E23=0,"nein",IF(OR(E23<>24,F22<>0,D23<>D22),"ja","nein")) -> nein | N23: =YEAR(B23) -> 2021
A24: =_xlfn.ISOWEEKNUM(B24) -> 3 | B24: 44215 | C24: Dienstag | D24: W | E24: =IF(VLOOKUP(D24,Budget!A:B,2,FALSE)<>0,IF(G24=0,24,24-G24),0) -> 0 | H24: =IF(E24=0,0,IF(M24="ja",(VLOOKUP(D24,Budget!A:F,6,FALSE)*(E24-(VLOOKUP(D24,Budget!A:F,3,FALSE)))),VLOOKUP($D24,Budget!$A$1:$F$19,6,FALSE)*E24)) -> 0 | I24: =IF(F24=0,0,IF(M24="ja",((VLOOKUP(F24,Budget!A:F,6,FALSE)*(E24-(VLOOKUP(F24,Budget!A:F,3,FALSE))))),VLOOKUP($D24,Budget!A:F,5,FALSE)*E24)) -> 0 | J24: =H24+I24 -> 0 | M24: =IF(E24=0,"nein",IF(OR(E24<>24,F23<>0,D24<>D23),"ja","nein")) -> nein | N24: =YEAR(B24) -> 2021
A25: =_xlfn.ISOWEEKNUM(B25) -> 3 | B25: 44216 | C25: Mittwoch | D25: W | E25: =IF(VLOOKUP(D25,Budget!A:B,2,FALSE)<>0,IF(G25=0,24,24-G25),0) -> 0 | H25: =IF(E25=0,0,IF(M25="ja",(VLOOKUP(D25,Budget!A:F,6,FALSE)*(E25-(VLOOKUP(D25,Budget!A:F,3,FALSE)))),VLOOKUP($D25,Budget!$A$1:$F$19,6,FALSE)*E25)) -> 0 | I25: =IF(F25=0,0,IF(M25="ja",((VLOOKUP(F25,Budget!A:F,6,FALSE)*(E25-(VLOOKUP(F25,Budget!A:F,3,FALSE))))),VLOOKUP($D25,Budget!A:F,5,FALSE)*E25)) -> 0 | J25: =H25+I25 -> 0 | M25: =IF(E25=0,"nein",IF(OR(E25<>24,F24<>0,D25<>D24),"ja","nein")) -> nein | N25: =YEAR(B25) -> 2021
A26: =_xlfn.ISOWEEKNUM(B26) -> 3 | B26: 44217 | C26: Donnerstag | D26: W | E26: =IF(VLOOKUP(D26,Budget!A:B,2,FALSE)<>0,IF(G26=0,24,24-G26),0) -> 0 | H26: =IF(E26=0,0,IF(M26="ja",(VLOOKUP(D26,Budget!A:F,6,FALSE)*(E26-(VLOOKUP(D26,Budget!A:F,3,FALSE)))),VLOOKUP($D26,Budget!$A$1:$F$19,6,FALSE)*E26)) -> 0 | I26: =IF(F26=0,0,IF(M26="ja",((VLOOKUP(F26,Budget!A:F,6,FALSE)*(E26-(VLOOKUP(F26,Budget!A:F,3,FALSE))))),VLOOKUP($D26,Budget!A:F,5,FALSE)*E26)) -> 0 | J26: =H26+I26 -> 0 | M26: =IF(E26=0,"nein",IF(OR(E26<>24,F25<>0,D26<>D25),"ja","nein")) -> nein | N26: =YEAR(B26) -> 2021
A27: =_xlfn.ISOWEEKNUM(B27) -> 3 | B27: 44218 | C27: Freitag | D27: K | E27: =IF(VLOOKUP(D27,Budget!A:B,2,FALSE)<>0,IF(G27=0,24,24-G27),0) -> 0 | H27: =IF(E27=0,0,IF(M27="ja",(VLOOKUP(D27,Budget!A:F,6,FALSE)*(E27-(VLOOKUP(D27,Budget!A:F,3,FALSE)))),VLOOKUP($D27,Budget!$A$1:$F$19,6,FALSE)*E27)) -> 0 | I27: =IF(F27=0,0,IF(M27="ja",((VLOOKUP(F27,Budget!A:F,6,FALSE)*(E27-(VLOOKUP(F27,Budget!A:F,3,FALSE))))),VLOOKUP($D27,Budget!A:F,5,FALSE)*E27)) -> 0 | J27: =H27+I27 -> 0 | M27: =IF(E27=0,"nein",IF(OR(E27<>24,F26<>0,D27<>D26),"ja","nein")) -> nein | N27: =YEAR(B27) -> 2021
A28: =_xlfn.ISOWEEKNUM(B28) -> 3 | B28: 44219 | C28: Samstag | D28: K | E28: =IF(VLOOKUP(D28,Budget!A:B,2,FALSE)<>0,IF(G28=0,24,24-G28),0) -> 0 | H28: =IF(E28=0,0,IF(M28="ja",(VLOOKUP(D28,Budget!A:F,6,FALSE)*(E28-(VLOOKUP(D28,Budget!A:F,3,FALSE)))),VLOOKUP($D28,Budget!$A$1:$F$19,6,FALSE)*E28)) -> 0 | I28: =IF(F28=0,0,IF(M28="ja",((VLOOKUP(F28,Budget!A:F,6,FALSE)*(E28-(VLOOKUP(F28,Budget!A:F,3,FALSE))))),VLOOKUP($D28,Budget!A:F,5,FALSE)*E28)) -> 0 | J28: =H28+I28 -> 0 | M28: =IF(E28=0,"nein",IF(OR(E28<>24,F27<>0,D28<>D27),"ja","nein")) -> nein | N28: =YEAR(B28) -> 2021
A29: =_xlfn.ISOWEEKNUM(B29) -> 3 | B29: 44220 | C29: Sonntag | D29: PLT XN | E29: 12 | H29: =IF(E29=0,0,IF(M29="ja",(VLOOKUP(D29,Budget!A:F,6,FALSE)*(E29-(VLOOKUP(D29,Budget!A:F,3,FALSE)))),VLOOKUP($D29,Budget!$A$1:$F$19,6,FALSE)*E29)) -> 16810.08 | I29: =IF(F29=0,0,IF(M29="ja",((VLOOKUP(F29,Budget!A:F,6,FALSE)*(E29-(VLOOKUP(F29,Budget!A:F,3,FALSE))))),VLOOKUP($D29,Budget!A:F,5,FALSE)*E29)) -> 0 | J29: =H29+I29 -> 16810.08 | M29: =IF(E29=0,"nein",IF(OR(E29<>24,F28<>0,D29<>D28),"ja","nein")) -> ja | N29: =YEAR(B29) -> 2021
A30: =_xlfn.ISOWEEKNUM(B30) -> 4 | B30: 44221 | C30: Montag | D30: PLT XN | E30: =IF(VLOOKUP(D30,Budget!A:B,2,FALSE)<>0,IF(G30=0,24,24-G30),0) -> 24 | H30: =IF(E30=0,0,IF(M30="ja",(VLOOKUP(D30,Budget!A:F,6,FALSE)*(E30-(VLOOKUP(D30,Budget!A:F,3,FALSE)))),VLOOKUP($D30,Budget!$A$1:$F$19,6,FALSE)*E30)) -> 42919.354 | I30: =IF(F30=0,0,IF(M30="ja",((VLOOKUP(F30,Budget!A:F,6,FALSE)*(E30-(VLOOKUP(F30,Budget!A:F,3,FALSE))))),VLOOKUP($D30,Budget!A:F,5,FALSE)*E30)) -> 0 | J30: =H30+I30 -> 42919.354 | M30: =IF(E30=0,"nein",IF(OR(E30<>24,F29<>0,D30<>D29),"ja","nein")) -> nein | N30: =YEAR(B30) -> 2021
A31: =_xlfn.ISOWEEKNUM(B31) -> 4 | B31: 44222 | C31: Dienstag | D31: ECLAZ | E31: =IF(VLOOKUP(D31,Budget!A:B,2,FALSE)<>0,IF(G31=0,24,24-G31),0) -> 24 | H31: =IF(E31=0,0,IF(M31="ja",(VLOOKUP(D31,Budget!A:F,6,FALSE)*(E31-(VLOOKUP(D31,Budget!A:F,3,FALSE)))),VLOOKUP($D31,Budget!$A$1:$F$19,6,FALSE)*E31)) -> 30030 | I31: =IF(F31=0,0,IF(M31="ja",((VLOOKUP(F31,Budget!A:F,6,FALSE)*(E31-(VLOOKUP(F31,Budget!A:F,3,FALSE))))),VLOOKUP($D31,Budget!A:F,5,FALSE)*E31)) -> 0 | J31: =H31+I31 -> 30030 | M31: =IF(E31=0,"nein",IF(OR(E31<>24,F30<>0,D31<>D30),"ja","nein")) -> ja | N31: =YEAR(B31) -> 2021
A32: =_xlfn.ISOWEEKNUM(B32) -> 4 | B32: 44223 | C32: Mittwoch | D32: ECLAZ | E32: =IF(VLOOKUP(D32,Budget!A:B,2,FALSE)<>0,IF(G32=0,24,24-G32),0) -> 24 | H32: =IF(E32=0,0,IF(M32="ja",(VLOOKUP(D32,Budget!A:F,6,FALSE)*(E32-(VLOOKUP(D32,Budget!A:F,3,FALSE)))),VLOOKUP($D32,Budget!$A$1:$F$19,6,FALSE)*E32)) -> 36960 | I32: =IF(F32=0,0,IF(M32="ja",((VLOOKUP(F32,Budget!A:F,6,FALSE)*(E32-(VLOOKUP(F32,Budget!A:F,3,FALSE))))),VLOOKUP($D32,Budget!A:F,5,FALSE)*E32)) -> 0 | J32: =H32+I32 -> 36960 | M32: =IF(E32=0,"nein",IF(OR(E32<>24,F31<>0,D32<>D31),"ja","nein")) -> nein | N32: =YEAR(B32) -> 2021
A33: =_xlfn.ISOWEEKNUM(B33) -> 4 | B33: 44224 | C33: Donnerstag | D33: ECLAZ | E33: =IF(VLOOKUP(D33,Budget!A:B,2,FALSE)<>0,IF(G33=0,24,24-G33),0) -> 24 | H33: =IF(E33=0,0,IF(M33="ja",(VLOOKUP(D33,Budget!A:F,6,FALSE)*(E33-(VLOOKUP(D33,Budget!A:F,3,FALSE)))),VLOOKUP($D33,Budget!$A$1:$F$19,6,FALSE)*E33)) -> 36960 | I33: =IF(F33=0,0,IF(M33="ja",((VLOOKUP(F33,Budget!A:F,6,FALSE)*(E33-(VLOOKUP(F33,Budget!A:F,3,FALSE))))),VLOOKUP($D33,Budget!A:F,5,FALSE)*E33)) -> 0 | J33: =H33+I33 -> 36960 | M33: =IF(E33=0,"nein",IF(OR(E33<>24,F32<>0,D33<>D32),"ja","nein")) -> nein | N33: =YEAR(B33) -> 2021
A34: =_xlfn.ISOWEEKNUM(B34) -> 4 | B34: 44225 | C34: Freitag | D34: ECLAZ | E34: =IF(VLOOKUP(D34,Budget!A:B,2,FALSE)<>0,IF(G34=0,24,24-G34),0) -> 24 | H34: =IF(E34=0,0,IF(M34="ja",(VLOOKUP(D34,Budget!A:F,6,FALSE)*(E34-(VLOOKUP(D34,Budget!A:F,3,FALSE)))),VLOOKUP($D34,Budget!$A$1:$F$19,6,FALSE)*E34)) -> 36960 | I34: =IF(F34=0,0,IF(M34="ja",((VLOOKUP(F34,Budget!A:F,6,FALSE)*(E34-(VLOOKUP(F34,Budget!A:F,3,FALSE))))),VLOOKUP($D34,Budget!A:F,5,FALSE)*E34)) -> 0 | J34: =H34+I34 -> 36960 | M34: =IF(E34=0,"nein",IF(OR(E34<>24,F33<>0,D34<>D33),"ja","nein")) -> nein | N34: =YEAR(B34) -> 2021
A35: =_xlfn.ISOWEEKNUM(B35) -> 4 | B35: 44226 | C35: Samstag | D35: ECLAZ | E35: =IF(VLOOKUP(D35,Budget!A:B,2,FALSE)<>0,IF(G35=0,24,24-G35),0) -> 24 | H35: =IF(E35=0,0,IF(M35="ja",(VLOOKUP(D35,Budget!A:F,6,FALSE)*(E35-(VLOOKUP(D35,Budget!A:F,3,FALSE)))),VLOOKUP($D35,Budget!$A$1:$F$19,6,FALSE)*E35)) -> 36960 | I35: =IF(F35=0,0,IF(M35="ja",((VLOOKUP(F35,Budget!A:F,6,FALSE)*(E35-(VLOOKUP(F35,Budget!A:F,3,FALSE))))),VLOOKUP($D35,Budget!A:F,5,FALSE)*E35)) -> 0 | J35: =H35+I35 -> 36960 | M35: =IF(E35=0,"nein",IF(OR(E35<>24,F34<>0,D35<>D34),"ja","nein")) -> nein | N35: =YEAR(B35) -> 2021
A36: =_xlfn.ISOWEEKNUM(B36) -> 4 | B36: 44227 | C36: Sonntag | D36: ECLAZ | E36: =IF(VLOOKUP(D36,Budget!A:B,2,FALSE)<>0,IF(G36=0,24,24-G36),0) -> 24 | H36: =IF(E36=0,0,IF(M36="ja",(VLOOKUP(D36,Budget!A:F,6,FALSE)*(E36-(VLOOKUP(D36,Budget!A:F,3,FALSE)))),VLOOKUP($D36,Budget!$A$1:$F$19,6,FALSE)*E36)) -> 36960 | I36: =IF(F36=0,0,IF(M36="ja",((VLOOKUP(F36,Budget!A:F,6,FALSE)*(E36-(VLOOKUP(F36,Budget!A:F,3,FALSE))))),VLOOKUP($D36,Budget!A:F,5,FALSE)*E36)) -> 0 | J36: =H36+I36 -> 36960 | M36: =IF(E36=0,"nein",IF(OR(E36<>24,F35<>0,D36<>D35),"ja","nein")) -> nein | N36: =YEAR(B36) -> 2021
A37: =_xlfn.ISOWEEKNUM(B37) -> 5 | B37: 44228 | C37: Montag | D37: ECLAZ | E37: =IF(VLOOKUP(D37,Budget!A:B,2,FALSE)<>0,IF(G37=0,24,24-G37),0) -> 24 | H37: =IF(E37=0,0,IF(M37="ja",(VLOOKUP(D37,Budget!A:F,6,FALSE)*(E37-(VLOOKUP(D37,Budget!A:F,3,FALSE)))),VLOOKUP($D37,Budget!$A$1:$F$19,6,FALSE)*E37)) -> 36960 | I37: =IF(F37=0,0,IF(M37="ja",((VLOOKUP(F37,Budget!A:F,6,FALSE)*(E37-(VLOOKUP(F37,Budget!A:F,3,FALSE))))),VLOOKUP($D37,Budget!A:F,5,FALSE)*E37)) -> 0 | J37: =H37+I37 -> 36960 | M37: =IF(E37=0,"nein",IF(OR(E37<>24,F36<>0,D37<>D36),"ja","nein")) -> nein | N37: =YEAR(B37) -> 2021
A38: =_xlfn.ISOWEEKNUM(B38) -> 5 | B38: 44229 | C38: Dienstag | D38: PLT XNII | E38: =IF(VLOOKUP(D38,Budget!A:B,2,FALSE)<>0,IF(G38=0,24,24-G38),0) -> 24 | H38: =IF(E38=0,0,IF(M38="ja",(VLOOKUP(D38,Budget!A:F,6,FALSE)*(E38-(VLOOKUP(D38,Budget!A:F,3,FALSE)))),VLOOKUP($D38,Budget!$A$1:$F$19,6,FALSE)*E38)) -> 22220.984 | I38: =IF(F38=0,0,IF(M38="ja",((VLOOKUP(F38,Budget!A:F,6,FALSE)*(E38-(VLOOKUP(F38,Budget!A:F,3,FALSE))))),VLOOKUP($D38,Budget!A:F,5,FALSE)*E38)) -> 0 | J38: =H38+I38 -> 22220.984 | M38: =IF(E38=0,"nein",IF(OR(E38<>24,F37<>0,D38<>D37),"ja","nein")) -> ja | N38: =YEAR(B38) -> 2021
A39: =_xlfn.ISOWEEKNUM(B39) -> 5 | B39: 44230 | C39: Mittwoch | D39: PLT XNII | E39: =IF(VLOOKUP(D39,Budget!A:B,2,FALSE)<>0,IF(G39=0,24,24-G39),0) -> 24 | H39: =IF(E39=0,0,IF(M39="ja",(VLOOKUP(D39,Budget!A:F,6,FALSE)*(E39-(VLOOKUP(D39,Budget!A:F,3,FALSE)))),VLOOKUP($D39,Budget!$A$1:$F$19,6,FALSE)*E39)) -> 35553.574 | I39: =IF(F39=0,0,IF(M39="ja",((VLOOKUP(F39,Budget!A:F,6,FALSE)*(E39-(VLOOKUP(F39,Budget!A:F,3,FALSE))))),VLOOKUP($D39,Budget!A:F,5,FALSE)*E39)) -> 0 | J39: =H39+I39 -> 35553.574 | M39: =IF(E39=0,"nein",IF(OR(E39<>24,F38<>0,D39<>D38),"ja","nein")) -> nein | N39: =YEAR(B39) -> 2021
A40: =_xlfn.ISOWEEKNUM(B40) -> 5 | B40: 44231 | C40: Donnerstag | D40: PLT XNII | E40: =IF(VLOOKUP(D40,Budget!A:B,2,FALSE)<>0,IF(G40=0,24,24-G40),0) -> 24 | H40: =IF(E40=0,0,IF(M40="ja",(VLOOKUP(D40,Budget!A:F,6,FALSE)*(E40-(VLOOKUP(D40,Budget!A:F,3,FALSE)))),VLOOKUP($D40,Budget!$A$1:$F$19,6,FALSE)*E40)) -> 35553.574 | I40: =IF(F40=0,0,IF(M40="ja",((VLOOKUP(F40,Budget!A:F,6,FALSE)*(E40-(VLOOKUP(F40,Budget!A:F,3,FALSE))))),VLOOKUP($D40,Budget!A:F,5,FALSE)*E40)) -> 0 | J40: =H40+I40 -> 35553.574 | M40: =IF(E40=0,"nein",IF(OR(E40<>24,F39<>0,D40<>D39),"ja","nein")) -> nein | N40: =YEAR(B40) -> 2021
...

Sheet Tabelle1
A1: Datum | B1: Wochen­tag | C1: Feiertag
A2: 44927 | B2: Sonntag | C2: Neujahrs­tag
A3: 45023 | B3: Freitag | C3: Karfreitag
A4: 45026 | B4: Montag | C4: Oster­montag
A5: 45047 | B5: Montag | C5: Tag der Arbeit / 1. Mai
A6: 45064 | B6: Donners­tag | C6: Christi Himmel­fahrt
A7: 45075 | B7: Montag | C7: Pfingst­montag
A8: 45085 | B8: Donners­tag | C8: Fronleich­nam
A14: 45202 | B14: Dienstag | C14: Tag der Deutschen Einheit
A15: 1. Novem­ber 2023 | B15: Mittwoch | C15: Aller­heiligen
A20: 25. Dezem­ber 2023 | B20: Montag | C20: 1. Weih­nachtstag
A21: 26. Dezem­ber 2023 | B21: Dienstag | C21: 2. Weih­nachtstag

Sheet Ofen
A1: Vorspannbare Produkte: | B1: PLT XNII
B2: VC II
B3: Timeless

Sheet Budget
A1: coating | B1: Geschw. (m/min) | C1: Einstellzeit (h) | D1: Mindestlänge (Tage) | E1: Maximallänge (Tage) | F1: Ausbringung Budget (m²/h) | G1: ="∑ Budget (m²) "&K1 -> ∑ Budget (m²) 2023 | H1: ="Planung (m²) "&K1 -> Planung (m²) 2023 | I1: Erwarteter Verbrauch Einstellglas (M²) | J1: ∑ Umstellungen | K1: 2023
A2: PLT XN | B2: 12 | C2: 2.6 | D2: 3 | F2: 1788.3064 | G2: 4309000 | H2: =SUMIFS(Planung!H:H,Planung!D:D,Budget!A2,Planung!N:N,Budget!$K$1) -> 4733647.1 | J2: =COUNTIFS(Planung!M:M,"ja",Planung!D:D,Budget!A2,Planung!N:N,Budget!$K$1) -> 25 | K2: =+G2-H2 -> -424647.06
A3: PLT ONE | B3: 10 | C3: 3 | D3: 1 | F3: 1539.4368 | G3: 120000 | H3: =SUMIFS(Planung!H:H,Planung!D:D,Budget!A3,Planung!N:N,Budget!$K$1) -> 69274.654 | J3: =COUNTIFS(Planung!M:M,"ja",Planung!D:D,Budget!A3,Planung!N:N,Budget!$K$1) -> 1 | K3: =+G3-H3 -> 50725.346
A4: ECLAZ | B4: 10 | C4: 4.5 | D4: 5 | F4: 1540 | G4: 4460000 | H4: =SUMIFS(Planung!H:H,Planung!D:D,Budget!A4,Planung!N:N,Budget!$K$1) -> 4303530 | J4: =COUNTIFS(Planung!M:M,"ja",Planung!D:D,Budget!A4,Planung!N:N,Budget!$K$1) -> 19 | K4: =+G4-H4 -> 156470
A5: VIEWCL II | C5: 0 | F5: 0 | H5: =SUMIFS(Planung!H:H,Planung!D:D,Budget!A5,Planung!N:N,Budget!$K$1) -> 0 | J5: =COUNTIFS(Planung!M:M,"ja",Planung!D:D,Budget!A5,Planung!N:N,Budget!$K$1) -> 0 | K5: =+G5-H5 -> 0
A6: PLT XNII | B6: 10 | C6: 9 | D6: 2 | E6: 0 | F6: 1481.3989 | G6: 60000 | H6: =SUMIFS(Planung!H:H,Planung!D:D,Budget!A6,Planung!N:N,Budget!$K$1) -> 0 | J6: =COUNTIFS(Planung!M:M,"ja",Planung!D:D,Budget!A6,Planung!N:N,Budget!$K$1) -> 0 | K6: =+G6-H6 -> 60000
A7: PLT VX | C7: 0 | F7: 0 | G7: 0 | H7: =SUMIFS(Planung!H:H,Planung!D:D,Budget!A7,Planung!N:N,Budget!$K$1) -> 0 | J7: =COUNTIFS(Planung!M:M,"ja",Planung!D:D,Budget!A7,Planung!N:N,Budget!$K$1) -> 0 | K7: =+G7-H7 -> 0
A8: TIMELESS | B8: 9 | C8: 3 | D8: 2 | F8: 1200 | G8: 200000 | H8: =SUMIFS(Planung!H:H,Planung!D:D,Budget!A8,Planung!N:N,Budget!$K$1) -> 144000 | J8: =COUNTIFS(Planung!M:M,"ja",Planung!D:D,Budget!A8,Planung!N:N,Budget!$K$1) -> 4 | K8: =+G8-H8 -> 56000
A9: ECLAZ ONE | B9: 10 | C9: 6 | D9: 4 | F9: 1540 | G9: 1026000 | H9: =SUMIFS(Planung!H:H,Planung!D:D,Budget!A9,Planung!N:N,Budget!$K$1) -> 1044120 | J9: =COUNTIFS(Planung!M:M,"ja",Planung!D:D,Budget!A9,Planung!N:N,Budget!$K$1) -> 11 | K9: =+G9-H9 -> -18120
A10: BIOCLEAN | B10: 3.3 | C10: 4 | D10: 2 | E10: 0 | F10: 492.18978 | G10: 47000 | H10: =SUMIFS(Planung!H:H,Planung!D:D,Budget!A10,Planung!N:N,Budget!$K$1) -> 33468.905 | J10: =COUNTIFS(Planung!M:M,"ja",Planung!D:D,Budget!A10,Planung!N:N,Budget!$K$1) -> 1 | K10: =+G10-H10 -> 13531.095
A11: W | F11: 0
A12: K | F12: 0
A13: SIGMA | B13: 0 | C13: 0 | D13: 0 | E13: 0 | F13: 0 | G13: 0 | H13: 0 | I13: 0 | J13: 0 | K13: 0
A14: INVEST | B14: 0 | C14: 0 | D14: 0 | E14: 0 | F14: 0 | G14: 0 | H14: 0 | I14: 0 | J14: 0 | K14: 0

Sheet Budget 2022
A1: coating | B1: Geschw. (m/min) | C1: Einstellzeit (h) | D1: Mindestlänge (Tage) | E1: Maximallänge (Tage) | F1: Ausbringung Budget (m²/h) | G1: ∑ Budget 2022 (m²) | H1: Planung 2022 (m²) | I1: Erwarteter Verbrauch Einstellglas (M²) | J1: ∑ Umstellungen
A2: BIOCLEAN | B2: 3.3 | C2: 4 | D2: 2 | E2: 4 | F2: 781 | G2: 80000 | H2: =SUMIF(Planung!D:I,A2,Planung!H:H)+SUMIF(Planung!D:I,A2,Planung!I:I) -> 270822.41 | I2: =J2*1167 -> 316257 | J2: =COUNTIF(Planung!M:M,"ja") -> 271 | K2: =+G2-H2 -> -190822.41
A3: ECLAZ | B3: 10 | C3: 5.5 | D3: 5 | F3: 1273 | G3: 3800000 | H3: =SUMIF(Planung!D:I,A3,Planung!H:H)+SUMIF(Planung!D:I,A3,Planung!I:I) -> 12375396 | K3: =+G3-H3 -> -8575395.6
A4: ECLAZ ONE | B4: 9 | C4: 6 | D4: 4 | F4: 1172 | G4: 1200000 | H4: =SUMIF(Planung!D:I,A4,Planung!H:H)+SUMIF(Planung!D:I,A4,Planung!I:I) -> 2934563.3 | K4: =+G4-H4 -> -1734563.3
A5: INVEST | B5: 0 | C5: 0 | D5: 0 | E5: 0 | F5: 0 | G5: 0 | H5: =SUMIF(Planung!D:I,A5,Planung!H:H)+SUMIF(Planung!D:I,A5,Planung!I:I) -> 0 | K5: =+G5-H5 -> 0
A6: K | B6: 0 | C6: 0 | D6: 0 | E6: 0 | F6: 0 | G6: 0 | H6: =SUMIF(Planung!D:I,A6,Planung!H:H)+SUMIF(Planung!D:I,A6,Planung!I:I) -> 33620.16 | K6: =+G6-H6 -> -33620.16
A7: PLT ONE | B7: 10 | C7: 3 | D7: 1 | F7: 1303 | G7: 400000 | H7: =SUMIF(Planung!D:I,A7,Planung!H:H)+SUMIF(Planung!D:I,A7,Planung!I:I) -> 878775.17 | K7: =+G7-H7 -> -478775.17
A8: PLT ONE II | B8: - | C8: - | F8: 1376 | G8: 0 | H8: =SUMIF(Planung!D:I,A8,Planung!H:H)+SUMIF(Planung!D:I,A8,Planung!I:I) -> 0 | K8: =+G8-H8 -> 0
A9: PV SINT | B9: 12 | C9: 2 | F9: 1904 | G9: 0 | H9: =SUMIF(Planung!D:I,A9,Planung!H:H)+SUMIF(Planung!D:I,A9,Planung!I:I) -> 0 | K9: =+G9-H9 -> 0
A10: SIGMA | B10: 0 | C10: 0 | D10: 0 | E10: 0 | F10: 0 | G10: 0 | H10: =SUMIF(Planung!D:I,A10,Planung!H:H)+SUMIF(Planung!D:I,A10,Planung!I:I) -> 188164.43 | K10: =+G10-H10 -> -188164.43
A11: TIMELESS | B11: 6 | C11: 4 | D11: 2 | F11: 781 | G11: 300000 | H11: =SUMIF(Planung!D:I,A11,Planung!H:H)+SUMIF(Planung!D:I,A11,Planung!I:I) -> #N/A | K11: =+G11-H11 -> #N/A
A12: PLT VX | B12: 10 | C12: 3 | F12: 1594 | G12: 0 | H12: =SUMIF(Planung!D:I,A12,Planung!H:H)+SUMIF(Planung!D:I,A12,Planung!I:I) -> 0 | K12: =+G12-H12 -> 0
A13: W | B13: 0 | C13: 0 | D13: 0 | E13: 0 | F13: 0 | G13: 0 | H13: =SUMIF(Planung!D:I,A13,Planung!H:H)+SUMIF(Planung!D:I,A13,Planung!I:I) -> 92440.078 | K13: =+G13-H13 -> -92440.078
A14: PLT XN | B14: 12 | C14: 2.6 | D14: 3 | E14: 7 | F14: 1617 | G14: 4000000 | H14: =SUMIF(Planung!D:I,A14,Planung!H:H)+SUMIF(Planung!D:I,A14,Planung!I:I) -> 13131724 | K14: =+G14-H14 -> -9131724.5
A15: PLT XN-T | B15: 12 | C15: 3 | F15: 1812 | G15: 0 | H15: =SUMIF(Planung!D:I,A15,Planung!H:H)+SUMIF(Planung!D:I,A15,Planung!I:I) -> 0 | K15: =+G15-H15 -> 0
A16: PLT XNII | B16: 10 | C16: 9 | D16: 2.5 | E16: 7 | F16: 1185 | G16: 410000 | H16: =SUMIF(Planung!D:I,A16,Planung!H:H)+SUMIF(Planung!D:I,A16,Planung!I:I) -> 1035497.8 | K16: =+G16-H16 -> -625497.84
A17: HS | B17: 0 | C17: 0 | D17: 0 | E17: 0 | F17: 0 | G17: 0 | H17: =SUMIF(Planung!D:I,A17,Planung!H:H)+SUMIF(Planung!D:I,A17,Planung!I:I) -> #N/A | K17: =+G17-H17 -> #N/A
A18: VIEWCL II | B18: 2 | C18: 18 | F18: 307 | G18: 0 | H18: =SUMIF(Planung!D:I,A18,Planung!H:H)+SUMIF(Planung!D:I,A18,Planung!I:I) -> 0 | K18: =+G18-H18 -> 0
B19: 0 | C19: 0 | D19: 0 | E19: 0 | F19: 0 | G19: 0 | H19: =SUMIF(Planung!D:I,A19,Planung!H:H)+SUMIF(Planung!D:I,A19,Planung!I:I) -> #N/A

Sheet 2019 (3)
B3: Einzel | C3: Mo-DI / Mi-Do | D3: Fr-So | E3: Mo-Do | F3: Fr-Di / Mi-So | G3: ganze Woche | I3: Einzel | J3: Mo-DI / Mi-Do | K3: Fr-So | L3: Mo-Do | M3: Fr-Di / Mi-So | N3: ganze Woche
B5: 38641.502 | C5: 123878.04 | D5: 166496.31 | E5: 209114.58 | F5: 251732.85 | G5: 336969.39 | I5: 21907.116 | J5: 87142.225 | K5: 119759.78 | L5: 152377.33 | M5: 184994.89 | N5: 250230
B6: PLT XN | C6: PLT XN | D6: PLT XN | E6: PLT XN | F6: PLT XN | G6: PLT XN | I6: PLT XNII | J6: PLT XNII | K6: PLT XNII | L6: PLT XNII | M6: PLT XNII | N6: PLT XNII
C7: PLT XN | D7: PLT XN | E7: PLT XN | F7: PLT XN | G7: PLT XN | J7: PLT XNII | K7: PLT XNII | L7: PLT XNII | M7: PLT XNII | N7: PLT XNII
D8: PLT XN | E8: PLT XN | F8: PLT XN | G8: PLT XN | K8: PLT XNII | L8: PLT XNII | M8: PLT XNII | N8: PLT XNII
E9: PLT XN | F9: PLT XN | G9: PLT XN | L9: PLT XNII | M9: PLT XNII | N9: PLT XNII
F10: PLT XN | G10: PLT XN | M10: PLT XNII | N10: PLT XNII
G11: PLT XN | N11: PLT XNII
G12: PLT XN | N12: PLT XNII
B14: 38980.383 | C14: 124894.68 | D14: 167851.83 | E14: 210808.98 | F14: 253766.14 | G14: 339680.44 | I14: 11965.675 | J14: 65991.481 | K14: 93004.384 | L14: 120017.29 | M14: 147030.19 | N14: 201055.99
B15: PLT XN-T | C15: PLT XN-T | D15: PLT XN-T | E15: PLT XN-T | F15: PLT XN-T | G15: PLT XN-T | I15: ECLAZ | J15: ECLAZ | K15: ECLAZ | L15: ECLAZ | M15: ECLAZ | N15: ECLAZ
C16: PLT XN-T | D16: PLT XN-T | E16: PLT XN-T | F16: PLT XN-T | G16: PLT XN-T | J16: ECLAZ | K16: ECLAZ | L16: ECLAZ | M16: ECLAZ | N16: ECLAZ
D17: PLT XN-T | E17: PLT XN-T | F17: PLT XN-T | G17: PLT XN-T | K17: ECLAZ | L17: ECLAZ | M17: ECLAZ | N17: ECLAZ
E18: PLT XN-T | F18: PLT XN-T | G18: PLT XN-T | L18: ECLAZ | M18: ECLAZ | N18: ECLAZ
F19: PLT XN-T | G19: PLT XN-T | M19: ECLAZ | N19: ECLAZ
G20: PLT XN-T | N20: ECLAZ
G21: PLT XN-T | N21: ECLAZ
B23: 27773.11 | C23: 98742.363 | D23: 134226.99 | E23: 169711.62 | F23: 205196.24 | G23: 276165.49 | I23: 13642.576 | J23: 71352.89 | K23: 100208.05 | L23: 129063.2 | M23: 157918.36 | N23: 215628.68
B24: PLT ONE | C24: PLT ONE | D24: PLT ONE | E24: PLT ONE | F24: PLT ONE | G24: PLT ONE | I24: ECLAZ ONE | J24: ECLAZ ONE | K24: ECLAZ ONE | L24: ECLAZ ONE | M24: ECLAZ ONE | N24: ECLAZ ONE
C25: PLT ONE | D25: PLT ONE | E25: PLT ONE | F25: PLT ONE | G25: PLT ONE | J25: ECLAZ ONE | K25: ECLAZ ONE | L25: ECLAZ ONE | M25: ECLAZ ONE | N25: ECLAZ ONE
D26: PLT ONE | E26: PLT ONE | F26: PLT ONE | G26: PLT ONE | K26: ECLAZ ONE | L26: ECLAZ ONE | M26: ECLAZ ONE | N26: ECLAZ ONE
E27: PLT ONE | F27: PLT ONE | G27: PLT ONE | K27: aber nicht WE | L27: ECLAZ ONE | M27: ECLAZ ONE | N27: ECLAZ ONE
F28: PLT ONE | G28: PLT ONE | M28: ECLAZ ONE | N28: ECLAZ ONE
G29: PLT ONE | N29: ECLAZ ONE
G30: PLT ONE | N30: ECLAZ ONE
B32: 29096.553 | C32: 103524.43 | D32: 140738.37 | E32: 177952.31 | F32: 215166.25 | G32: 289594.12 | I32: 7387.0727 | J32: 29517.882 | K32: 40583.287 | L32: 51648.692 | M32: 62714.097 | N32: 84844.907
B33: LUX | C33: LUX | D33: LUX | E33: LUX | F33: LUX | G33: LUX | I33: BioClean TOP | J33: BioClean TOP | K33: BioClean TOP | L33: BioClean TOP | M33: BioClean TOP | N33: BioClean TOP
C34: LUX | D34: LUX | E34: LUX | F34: LUX | G34: LUX | J34: BioClean TOP | K34: BioClean TOP | L34: BioClean TOP | M34: BioClean TOP | N34: BioClean TOP
D35: LUX | E35: LUX | F35: LUX | G35: LUX | K35: BioClean TOP | L35: BioClean TOP | M35: BioClean TOP | N35: BioClean TOP
E36: LUX | F36: LUX | G36: LUX | K36: aber nicht WE | L36: BioClean TOP | M36: BioClean TOP | N36: BioClean TOP
F37: LUX | G37: LUX | M37: BioClean TOP | N37: BioClean TOP
G38: LUX | N38: BioClean TOP
G39: LUX | N39: BioClean TOP
B41: 31850.507 | C41: 106487.44 | D41: 143805.91 | E41: 181124.38 | F41: 218442.85 | G41: 293079.79
B42: VX | C42: VX | D42: VX | E42: VX | F42: VX | G42: VX | I42: Kampagne kürzer als vorgesehen (oder WE für Sigma)
C43: VX | D43: VX | E43: VX | F43: VX | G43: VX | I43: Kampagne nach Plan
D44: VX | E44: VX | F44: VX | G44: VX | I44: Kampagne länger als vorgesehen
E45: VX | F45: VX | G45: VX | I45: wegen Jahresmengen in der Regel nicht realisierbar
F46: VX | G46: VX
G47: VX
...
